[2023-08-23 09:34:59,746] [autoreload.py:637] [autoreload:run_with_reloader] [INFO]- Watching for file changes with StatReloader
[2023-08-23 09:35:03,949] [basehttp.py:161] [basehttp:log_message] [INFO]- "GET / HTTP/1.1" 302 0
[2023-08-23 09:35:04,166] [basehttp.py:161] [basehttp:log_message] [INFO]- "GET /api/docs/ HTTP/1.1" 200 160128
[2023-08-23 09:35:04,206] [basehttp.py:161] [basehttp:log_message] [INFO]- "GET /static/rest_framework/css/bootstrap.min.css HTTP/1.1" 304 0
[2023-08-23 09:35:04,207] [basehttp.py:161] [basehttp:log_message] [INFO]- "GET /static/rest_framework/css/bootstrap-theme.min.css HTTP/1.1" 304 0
[2023-08-23 09:35:04,213] [basehttp.py:161] [basehttp:log_message] [INFO]- "GET /static/rest_framework/css/font-awesome-4.0.3.css HTTP/1.1" 304 0
[2023-08-23 09:35:04,243] [basehttp.py:161] [basehttp:log_message] [INFO]- "GET /static/rest_framework/docs/css/base.css HTTP/1.1" 304 0
[2023-08-23 09:35:04,263] [basehttp.py:161] [basehttp:log_message] [INFO]- "GET /static/rest_framework/docs/css/jquery.json-view.min.css HTTP/1.1" 304 0
[2023-08-23 09:35:04,264] [basehttp.py:161] [basehttp:log_message] [INFO]- "GET /static/rest_framework/js/coreapi-0.1.1.js HTTP/1.1" 304 0
[2023-08-23 09:35:04,267] [basehttp.py:161] [basehttp:log_message] [INFO]- "GET /static/rest_framework/js/jquery-3.5.1.min.js HTTP/1.1" 304 0
[2023-08-23 09:35:04,269] [basehttp.py:161] [basehttp:log_message] [INFO]- "GET /api/docs/schema.js HTTP/1.1" 200 24396
[2023-08-23 09:35:04,272] [basehttp.py:161] [basehttp:log_message] [INFO]- "GET /static/rest_framework/js/bootstrap.min.js HTTP/1.1" 304 0
[2023-08-23 09:35:04,274] [basehttp.py:161] [basehttp:log_message] [INFO]- "GET /static/rest_framework/docs/js/api.js HTTP/1.1" 304 0
[2023-08-23 09:35:04,275] [basehttp.py:161] [basehttp:log_message] [INFO]- "GET /static/rest_framework/docs/js/jquery.json-view.min.js HTTP/1.1" 304 0
[2023-08-23 09:35:04,395] [basehttp.py:161] [basehttp:log_message] [INFO]- "GET /static/rest_framework/fonts/fontawesome-webfont.woff?v=4.0.3 HTTP/1.1" 304 0
[2023-08-23 09:35:32,073] [basehttp.py:161] [basehttp:log_message] [INFO]- "POST /api/token/ HTTP/1.1" 200 576
[2023-08-23 09:37:35,120] [log.py:224] [log:log_response] [ERROR]- Internal Server Error: /api/system/user/
Traceback (most recent call last):
  File "D:\anaconda3\envs\Django\lib\site-packages\django_redis\cache.py", line 29, in _decorator
    return method(self, *args, **kwargs)
  File "D:\anaconda3\envs\Django\lib\site-packages\django_redis\cache.py", line 99, in _get
    return self.client.get(key, default=default, version=version, client=client)
  File "D:\anaconda3\envs\Django\lib\site-packages\django_redis\client\default.py", line 260, in get
    raise ConnectionInterrupted(connection=client) from e
django_redis.exceptions.ConnectionInterrupted: Redis ConnectionError: Error 11001 connecting to redis:6379. getaddrinfo failed.

During handling of the above exception, another exception occurred:

Traceback (most recent call last):
  File "D:\anaconda3\envs\Django\lib\site-packages\django\core\handlers\exception.py", line 47, in inner
    response = get_response(request)
  File "D:\anaconda3\envs\Django\lib\site-packages\django\core\handlers\base.py", line 181, in _get_response
    response = wrapped_callback(request, *callback_args, **callback_kwargs)
  File "D:\anaconda3\envs\Django\lib\site-packages\django\views\decorators\csrf.py", line 54, in wrapped_view
    return view_func(*args, **kwargs)
  File "D:\anaconda3\envs\Django\lib\site-packages\rest_framework\viewsets.py", line 125, in view
    return self.dispatch(request, *args, **kwargs)
  File "D:\anaconda3\envs\Django\lib\site-packages\rest_framework\views.py", line 509, in dispatch
    response = self.handle_exception(exc)
  File "D:\anaconda3\envs\Django\lib\site-packages\rest_framework\views.py", line 469, in handle_exception
    self.raise_uncaught_exception(exc)
  File "D:\anaconda3\envs\Django\lib\site-packages\rest_framework\views.py", line 480, in raise_uncaught_exception
    raise exc
  File "D:\anaconda3\envs\Django\lib\site-packages\rest_framework\views.py", line 497, in dispatch
    self.initial(request, *args, **kwargs)
  File "D:\anaconda3\envs\Django\lib\site-packages\rest_framework\views.py", line 415, in initial
    self.check_permissions(request)
  File "D:\anaconda3\envs\Django\lib\site-packages\rest_framework\views.py", line 332, in check_permissions
    if not permission.has_permission(request, self):
  File "E:\Work File\Background\BackEndServer\apps\system\permission.py", line 36, in has_permission
    perms = cache.get(request.user.username + '__perms')
  File "D:\anaconda3\envs\Django\lib\site-packages\django_redis\cache.py", line 92, in get
    value = self._get(key, default, version, client)
  File "D:\anaconda3\envs\Django\lib\site-packages\django_redis\cache.py", line 36, in _decorator
    raise e.__cause__
  File "D:\anaconda3\envs\Django\lib\site-packages\django_redis\client\default.py", line 258, in get
    value = client.get(key)
  File "D:\anaconda3\envs\Django\lib\site-packages\redis\commands\core.py", line 1829, in get
    return self.execute_command("GET", name)
  File "D:\anaconda3\envs\Django\lib\site-packages\redis\client.py", line 505, in execute_command
    conn = self.connection or pool.get_connection(command_name, **options)
  File "D:\anaconda3\envs\Django\lib\site-packages\redis\connection.py", line 1073, in get_connection
    connection.connect()
  File "D:\anaconda3\envs\Django\lib\site-packages\redis\connection.py", line 265, in connect
    raise ConnectionError(self._error_message(e))
redis.exceptions.ConnectionError: Error 11001 connecting to redis:6379. getaddrinfo failed.
[2023-08-23 09:37:35,146] [basehttp.py:161] [basehttp:log_message] [ERROR]- "GET /api/system/user/ HTTP/1.1" 500 154335
[2023-08-23 09:41:46,733] [log.py:224] [log:log_response] [ERROR]- Internal Server Error: /api/system/groups/
Traceback (most recent call last):
  File "D:\anaconda3\envs\Django\lib\site-packages\django_redis\cache.py", line 29, in _decorator
    return method(self, *args, **kwargs)
  File "D:\anaconda3\envs\Django\lib\site-packages\django_redis\cache.py", line 99, in _get
    return self.client.get(key, default=default, version=version, client=client)
  File "D:\anaconda3\envs\Django\lib\site-packages\django_redis\client\default.py", line 260, in get
    raise ConnectionInterrupted(connection=client) from e
django_redis.exceptions.ConnectionInterrupted: Redis ConnectionError: Error 11001 connecting to redis:6379. getaddrinfo failed.

During handling of the above exception, another exception occurred:

Traceback (most recent call last):
  File "D:\anaconda3\envs\Django\lib\site-packages\django\core\handlers\exception.py", line 47, in inner
    response = get_response(request)
  File "D:\anaconda3\envs\Django\lib\site-packages\django\core\handlers\base.py", line 181, in _get_response
    response = wrapped_callback(request, *callback_args, **callback_kwargs)
  File "D:\anaconda3\envs\Django\lib\site-packages\django\views\decorators\csrf.py", line 54, in wrapped_view
    return view_func(*args, **kwargs)
  File "D:\anaconda3\envs\Django\lib\site-packages\rest_framework\viewsets.py", line 125, in view
    return self.dispatch(request, *args, **kwargs)
  File "D:\anaconda3\envs\Django\lib\site-packages\rest_framework\views.py", line 509, in dispatch
    response = self.handle_exception(exc)
  File "D:\anaconda3\envs\Django\lib\site-packages\rest_framework\views.py", line 469, in handle_exception
    self.raise_uncaught_exception(exc)
  File "D:\anaconda3\envs\Django\lib\site-packages\rest_framework\views.py", line 480, in raise_uncaught_exception
    raise exc
  File "D:\anaconda3\envs\Django\lib\site-packages\rest_framework\views.py", line 497, in dispatch
    self.initial(request, *args, **kwargs)
  File "D:\anaconda3\envs\Django\lib\site-packages\rest_framework\views.py", line 415, in initial
    self.check_permissions(request)
  File "D:\anaconda3\envs\Django\lib\site-packages\rest_framework\views.py", line 332, in check_permissions
    if not permission.has_permission(request, self):
  File "E:\Work File\Background\BackEndServer\apps\system\permission.py", line 36, in has_permission
    perms = cache.get(request.user.username + '__perms')
  File "D:\anaconda3\envs\Django\lib\site-packages\django_redis\cache.py", line 92, in get
    value = self._get(key, default, version, client)
  File "D:\anaconda3\envs\Django\lib\site-packages\django_redis\cache.py", line 36, in _decorator
    raise e.__cause__
  File "D:\anaconda3\envs\Django\lib\site-packages\django_redis\client\default.py", line 258, in get
    value = client.get(key)
  File "D:\anaconda3\envs\Django\lib\site-packages\redis\commands\core.py", line 1829, in get
    return self.execute_command("GET", name)
  File "D:\anaconda3\envs\Django\lib\site-packages\redis\client.py", line 505, in execute_command
    conn = self.connection or pool.get_connection(command_name, **options)
  File "D:\anaconda3\envs\Django\lib\site-packages\redis\connection.py", line 1073, in get_connection
    connection.connect()
  File "D:\anaconda3\envs\Django\lib\site-packages\redis\connection.py", line 265, in connect
    raise ConnectionError(self._error_message(e))
redis.exceptions.ConnectionError: Error 11001 connecting to redis:6379. getaddrinfo failed.
[2023-08-23 09:41:46,742] [basehttp.py:161] [basehttp:log_message] [ERROR]- "GET /api/system/groups/ HTTP/1.1" 500 154391
[2023-08-23 09:45:05,579] [autoreload.py:251] [autoreload:trigger_reload] [INFO]- E:\Work File\Background\BackEndServer\config.py changed, reloading.
[2023-08-23 09:45:14,604] [autoreload.py:637] [autoreload:run_with_reloader] [INFO]- Watching for file changes with StatReloader
[2023-08-23 09:47:03,057] [basehttp.py:161] [basehttp:log_message] [INFO]- "GET / HTTP/1.1" 302 0
[2023-08-23 09:47:03,310] [basehttp.py:161] [basehttp:log_message] [INFO]- "GET /api/docs/ HTTP/1.1" 200 160128
[2023-08-23 09:47:03,391] [basehttp.py:161] [basehttp:log_message] [INFO]- "GET /api/docs/schema.js HTTP/1.1" 200 24396
[2023-08-23 09:47:14,548] [log.py:224] [log:log_response] [ERROR]- Internal Server Error: /api/system/groups/
Traceback (most recent call last):
  File "D:\anaconda3\envs\Django\lib\site-packages\django_redis\cache.py", line 29, in _decorator
    return method(self, *args, **kwargs)
  File "D:\anaconda3\envs\Django\lib\site-packages\django_redis\cache.py", line 99, in _get
    return self.client.get(key, default=default, version=version, client=client)
  File "D:\anaconda3\envs\Django\lib\site-packages\django_redis\client\default.py", line 260, in get
    raise ConnectionInterrupted(connection=client) from e
django_redis.exceptions.ConnectionInterrupted: Redis ConnectionError: Error 11001 connecting to redis:6379. getaddrinfo failed.

During handling of the above exception, another exception occurred:

Traceback (most recent call last):
  File "D:\anaconda3\envs\Django\lib\site-packages\django\core\handlers\exception.py", line 47, in inner
    response = get_response(request)
  File "D:\anaconda3\envs\Django\lib\site-packages\django\core\handlers\base.py", line 181, in _get_response
    response = wrapped_callback(request, *callback_args, **callback_kwargs)
  File "D:\anaconda3\envs\Django\lib\site-packages\django\views\decorators\csrf.py", line 54, in wrapped_view
    return view_func(*args, **kwargs)
  File "D:\anaconda3\envs\Django\lib\site-packages\rest_framework\viewsets.py", line 125, in view
    return self.dispatch(request, *args, **kwargs)
  File "D:\anaconda3\envs\Django\lib\site-packages\rest_framework\views.py", line 509, in dispatch
    response = self.handle_exception(exc)
  File "D:\anaconda3\envs\Django\lib\site-packages\rest_framework\views.py", line 469, in handle_exception
    self.raise_uncaught_exception(exc)
  File "D:\anaconda3\envs\Django\lib\site-packages\rest_framework\views.py", line 480, in raise_uncaught_exception
    raise exc
  File "D:\anaconda3\envs\Django\lib\site-packages\rest_framework\views.py", line 497, in dispatch
    self.initial(request, *args, **kwargs)
  File "D:\anaconda3\envs\Django\lib\site-packages\rest_framework\views.py", line 415, in initial
    self.check_permissions(request)
  File "D:\anaconda3\envs\Django\lib\site-packages\rest_framework\views.py", line 332, in check_permissions
    if not permission.has_permission(request, self):
  File "E:\Work File\Background\BackEndServer\apps\system\permission.py", line 36, in has_permission
    perms = cache.get(request.user.username + '__perms')
  File "D:\anaconda3\envs\Django\lib\site-packages\django_redis\cache.py", line 92, in get
    value = self._get(key, default, version, client)
  File "D:\anaconda3\envs\Django\lib\site-packages\django_redis\cache.py", line 36, in _decorator
    raise e.__cause__
  File "D:\anaconda3\envs\Django\lib\site-packages\django_redis\client\default.py", line 258, in get
    value = client.get(key)
  File "D:\anaconda3\envs\Django\lib\site-packages\redis\commands\core.py", line 1829, in get
    return self.execute_command("GET", name)
  File "D:\anaconda3\envs\Django\lib\site-packages\redis\client.py", line 505, in execute_command
    conn = self.connection or pool.get_connection(command_name, **options)
  File "D:\anaconda3\envs\Django\lib\site-packages\redis\connection.py", line 1073, in get_connection
    connection.connect()
  File "D:\anaconda3\envs\Django\lib\site-packages\redis\connection.py", line 265, in connect
    raise ConnectionError(self._error_message(e))
redis.exceptions.ConnectionError: Error 11001 connecting to redis:6379. getaddrinfo failed.
[2023-08-23 09:47:14,562] [basehttp.py:161] [basehttp:log_message] [ERROR]- "GET /api/system/groups/ HTTP/1.1" 500 154337
[2023-08-23 09:47:36,790] [autoreload.py:251] [autoreload:trigger_reload] [INFO]- E:\Work File\Background\BackEndServer\config.py changed, reloading.
[2023-08-23 09:47:39,161] [autoreload.py:637] [autoreload:run_with_reloader] [INFO]- Watching for file changes with StatReloader
[2023-08-23 09:47:52,753] [log.py:224] [log:log_response] [ERROR]- Internal Server Error: /api/system/groups/
Traceback (most recent call last):
  File "D:\anaconda3\envs\Django\lib\site-packages\django_redis\cache.py", line 29, in _decorator
    return method(self, *args, **kwargs)
  File "D:\anaconda3\envs\Django\lib\site-packages\django_redis\cache.py", line 99, in _get
    return self.client.get(key, default=default, version=version, client=client)
  File "D:\anaconda3\envs\Django\lib\site-packages\django_redis\client\default.py", line 260, in get
    raise ConnectionInterrupted(connection=client) from e
django_redis.exceptions.ConnectionInterrupted: Redis ConnectionError: Error 11001 connecting to redis:6379. getaddrinfo failed.

During handling of the above exception, another exception occurred:

Traceback (most recent call last):
  File "D:\anaconda3\envs\Django\lib\site-packages\django\core\handlers\exception.py", line 47, in inner
    response = get_response(request)
  File "D:\anaconda3\envs\Django\lib\site-packages\django\core\handlers\base.py", line 181, in _get_response
    response = wrapped_callback(request, *callback_args, **callback_kwargs)
  File "D:\anaconda3\envs\Django\lib\site-packages\django\views\decorators\csrf.py", line 54, in wrapped_view
    return view_func(*args, **kwargs)
  File "D:\anaconda3\envs\Django\lib\site-packages\rest_framework\viewsets.py", line 125, in view
    return self.dispatch(request, *args, **kwargs)
  File "D:\anaconda3\envs\Django\lib\site-packages\rest_framework\views.py", line 509, in dispatch
    response = self.handle_exception(exc)
  File "D:\anaconda3\envs\Django\lib\site-packages\rest_framework\views.py", line 469, in handle_exception
    self.raise_uncaught_exception(exc)
  File "D:\anaconda3\envs\Django\lib\site-packages\rest_framework\views.py", line 480, in raise_uncaught_exception
    raise exc
  File "D:\anaconda3\envs\Django\lib\site-packages\rest_framework\views.py", line 497, in dispatch
    self.initial(request, *args, **kwargs)
  File "D:\anaconda3\envs\Django\lib\site-packages\rest_framework\views.py", line 415, in initial
    self.check_permissions(request)
  File "D:\anaconda3\envs\Django\lib\site-packages\rest_framework\views.py", line 332, in check_permissions
    if not permission.has_permission(request, self):
  File "E:\Work File\Background\BackEndServer\apps\system\permission.py", line 36, in has_permission
    perms = cache.get(request.user.username + '__perms')
  File "D:\anaconda3\envs\Django\lib\site-packages\django_redis\cache.py", line 92, in get
    value = self._get(key, default, version, client)
  File "D:\anaconda3\envs\Django\lib\site-packages\django_redis\cache.py", line 36, in _decorator
    raise e.__cause__
  File "D:\anaconda3\envs\Django\lib\site-packages\django_redis\client\default.py", line 258, in get
    value = client.get(key)
  File "D:\anaconda3\envs\Django\lib\site-packages\redis\commands\core.py", line 1829, in get
    return self.execute_command("GET", name)
  File "D:\anaconda3\envs\Django\lib\site-packages\redis\client.py", line 505, in execute_command
    conn = self.connection or pool.get_connection(command_name, **options)
  File "D:\anaconda3\envs\Django\lib\site-packages\redis\connection.py", line 1073, in get_connection
    connection.connect()
  File "D:\anaconda3\envs\Django\lib\site-packages\redis\connection.py", line 265, in connect
    raise ConnectionError(self._error_message(e))
redis.exceptions.ConnectionError: Error 11001 connecting to redis:6379. getaddrinfo failed.
[2023-08-23 09:47:52,766] [basehttp.py:161] [basehttp:log_message] [ERROR]- "GET /api/system/groups/ HTTP/1.1" 500 154391
[2023-08-23 09:51:05,647] [log.py:224] [log:log_response] [ERROR]- Internal Server Error: /api/system/groups/
Traceback (most recent call last):
  File "D:\anaconda3\envs\Django\lib\site-packages\django_redis\cache.py", line 29, in _decorator
    return method(self, *args, **kwargs)
  File "D:\anaconda3\envs\Django\lib\site-packages\django_redis\cache.py", line 99, in _get
    return self.client.get(key, default=default, version=version, client=client)
  File "D:\anaconda3\envs\Django\lib\site-packages\django_redis\client\default.py", line 260, in get
    raise ConnectionInterrupted(connection=client) from e
django_redis.exceptions.ConnectionInterrupted: Redis ConnectionError: Error 11001 connecting to redis:6379. getaddrinfo failed.

During handling of the above exception, another exception occurred:

Traceback (most recent call last):
  File "D:\anaconda3\envs\Django\lib\site-packages\django\core\handlers\exception.py", line 47, in inner
    response = get_response(request)
  File "D:\anaconda3\envs\Django\lib\site-packages\django\core\handlers\base.py", line 181, in _get_response
    response = wrapped_callback(request, *callback_args, **callback_kwargs)
  File "D:\anaconda3\envs\Django\lib\site-packages\django\views\decorators\csrf.py", line 54, in wrapped_view
    return view_func(*args, **kwargs)
  File "D:\anaconda3\envs\Django\lib\site-packages\rest_framework\viewsets.py", line 125, in view
    return self.dispatch(request, *args, **kwargs)
  File "D:\anaconda3\envs\Django\lib\site-packages\rest_framework\views.py", line 509, in dispatch
    response = self.handle_exception(exc)
  File "D:\anaconda3\envs\Django\lib\site-packages\rest_framework\views.py", line 469, in handle_exception
    self.raise_uncaught_exception(exc)
  File "D:\anaconda3\envs\Django\lib\site-packages\rest_framework\views.py", line 480, in raise_uncaught_exception
    raise exc
  File "D:\anaconda3\envs\Django\lib\site-packages\rest_framework\views.py", line 497, in dispatch
    self.initial(request, *args, **kwargs)
  File "D:\anaconda3\envs\Django\lib\site-packages\rest_framework\views.py", line 415, in initial
    self.check_permissions(request)
  File "D:\anaconda3\envs\Django\lib\site-packages\rest_framework\views.py", line 332, in check_permissions
    if not permission.has_permission(request, self):
  File "E:\Work File\Background\BackEndServer\apps\system\permission.py", line 36, in has_permission
    perms = cache.get(request.user.username + '__perms')
  File "D:\anaconda3\envs\Django\lib\site-packages\django_redis\cache.py", line 92, in get
    value = self._get(key, default, version, client)
  File "D:\anaconda3\envs\Django\lib\site-packages\django_redis\cache.py", line 36, in _decorator
    raise e.__cause__
  File "D:\anaconda3\envs\Django\lib\site-packages\django_redis\client\default.py", line 258, in get
    value = client.get(key)
  File "D:\anaconda3\envs\Django\lib\site-packages\redis\commands\core.py", line 1829, in get
    return self.execute_command("GET", name)
  File "D:\anaconda3\envs\Django\lib\site-packages\redis\client.py", line 505, in execute_command
    conn = self.connection or pool.get_connection(command_name, **options)
  File "D:\anaconda3\envs\Django\lib\site-packages\redis\connection.py", line 1073, in get_connection
    connection.connect()
  File "D:\anaconda3\envs\Django\lib\site-packages\redis\connection.py", line 265, in connect
    raise ConnectionError(self._error_message(e))
redis.exceptions.ConnectionError: Error 11001 connecting to redis:6379. getaddrinfo failed.
[2023-08-23 09:51:05,656] [basehttp.py:161] [basehttp:log_message] [ERROR]- "GET /api/system/groups/ HTTP/1.1" 500 154391
[2023-08-23 09:51:11,852] [basehttp.py:161] [basehttp:log_message] [INFO]- "GET /api/docs/ HTTP/1.1" 200 160128
[2023-08-23 09:51:11,996] [basehttp.py:161] [basehttp:log_message] [INFO]- "GET /api/docs/schema.js HTTP/1.1" 200 24396
[2023-08-23 09:51:12,316] [basehttp.py:161] [basehttp:log_message] [INFO]- "GET /static/rest_framework/docs/img/favicon.ico HTTP/1.1" 304 0
[2023-08-23 09:51:27,907] [log.py:224] [log:log_response] [ERROR]- Internal Server Error: /api/system/groups/1/
Traceback (most recent call last):
  File "D:\anaconda3\envs\Django\lib\site-packages\django_redis\cache.py", line 29, in _decorator
    return method(self, *args, **kwargs)
  File "D:\anaconda3\envs\Django\lib\site-packages\django_redis\cache.py", line 99, in _get
    return self.client.get(key, default=default, version=version, client=client)
  File "D:\anaconda3\envs\Django\lib\site-packages\django_redis\client\default.py", line 260, in get
    raise ConnectionInterrupted(connection=client) from e
django_redis.exceptions.ConnectionInterrupted: Redis ConnectionError: Error 11001 connecting to redis:6379. getaddrinfo failed.

During handling of the above exception, another exception occurred:

Traceback (most recent call last):
  File "D:\anaconda3\envs\Django\lib\site-packages\django\core\handlers\exception.py", line 47, in inner
    response = get_response(request)
  File "D:\anaconda3\envs\Django\lib\site-packages\django\core\handlers\base.py", line 181, in _get_response
    response = wrapped_callback(request, *callback_args, **callback_kwargs)
  File "D:\anaconda3\envs\Django\lib\site-packages\django\views\decorators\csrf.py", line 54, in wrapped_view
    return view_func(*args, **kwargs)
  File "D:\anaconda3\envs\Django\lib\site-packages\rest_framework\viewsets.py", line 125, in view
    return self.dispatch(request, *args, **kwargs)
  File "D:\anaconda3\envs\Django\lib\site-packages\rest_framework\views.py", line 509, in dispatch
    response = self.handle_exception(exc)
  File "D:\anaconda3\envs\Django\lib\site-packages\rest_framework\views.py", line 469, in handle_exception
    self.raise_uncaught_exception(exc)
  File "D:\anaconda3\envs\Django\lib\site-packages\rest_framework\views.py", line 480, in raise_uncaught_exception
    raise exc
  File "D:\anaconda3\envs\Django\lib\site-packages\rest_framework\views.py", line 497, in dispatch
    self.initial(request, *args, **kwargs)
  File "D:\anaconda3\envs\Django\lib\site-packages\rest_framework\views.py", line 415, in initial
    self.check_permissions(request)
  File "D:\anaconda3\envs\Django\lib\site-packages\rest_framework\views.py", line 332, in check_permissions
    if not permission.has_permission(request, self):
  File "E:\Work File\Background\BackEndServer\apps\system\permission.py", line 36, in has_permission
    perms = cache.get(request.user.username + '__perms')
  File "D:\anaconda3\envs\Django\lib\site-packages\django_redis\cache.py", line 92, in get
    value = self._get(key, default, version, client)
  File "D:\anaconda3\envs\Django\lib\site-packages\django_redis\cache.py", line 36, in _decorator
    raise e.__cause__
  File "D:\anaconda3\envs\Django\lib\site-packages\django_redis\client\default.py", line 258, in get
    value = client.get(key)
  File "D:\anaconda3\envs\Django\lib\site-packages\redis\commands\core.py", line 1829, in get
    return self.execute_command("GET", name)
  File "D:\anaconda3\envs\Django\lib\site-packages\redis\client.py", line 505, in execute_command
    conn = self.connection or pool.get_connection(command_name, **options)
  File "D:\anaconda3\envs\Django\lib\site-packages\redis\connection.py", line 1073, in get_connection
    connection.connect()
  File "D:\anaconda3\envs\Django\lib\site-packages\redis\connection.py", line 265, in connect
    raise ConnectionError(self._error_message(e))
redis.exceptions.ConnectionError: Error 11001 connecting to redis:6379. getaddrinfo failed.
[2023-08-23 09:51:27,915] [basehttp.py:161] [basehttp:log_message] [ERROR]- "GET /api/system/groups/1/ HTTP/1.1" 500 154744
[2023-08-23 09:51:43,878] [log.py:224] [log:log_response] [ERROR]- Internal Server Error: /api/system/permissions/
Traceback (most recent call last):
  File "D:\anaconda3\envs\Django\lib\site-packages\django_redis\cache.py", line 29, in _decorator
    return method(self, *args, **kwargs)
  File "D:\anaconda3\envs\Django\lib\site-packages\django_redis\cache.py", line 99, in _get
    return self.client.get(key, default=default, version=version, client=client)
  File "D:\anaconda3\envs\Django\lib\site-packages\django_redis\client\default.py", line 260, in get
    raise ConnectionInterrupted(connection=client) from e
django_redis.exceptions.ConnectionInterrupted: Redis ConnectionError: Error 11001 connecting to redis:6379. getaddrinfo failed.

During handling of the above exception, another exception occurred:

Traceback (most recent call last):
  File "D:\anaconda3\envs\Django\lib\site-packages\django\core\handlers\exception.py", line 47, in inner
    response = get_response(request)
  File "D:\anaconda3\envs\Django\lib\site-packages\django\core\handlers\base.py", line 181, in _get_response
    response = wrapped_callback(request, *callback_args, **callback_kwargs)
  File "D:\anaconda3\envs\Django\lib\site-packages\django\views\decorators\csrf.py", line 54, in wrapped_view
    return view_func(*args, **kwargs)
  File "D:\anaconda3\envs\Django\lib\site-packages\rest_framework\viewsets.py", line 125, in view
    return self.dispatch(request, *args, **kwargs)
  File "D:\anaconda3\envs\Django\lib\site-packages\rest_framework\views.py", line 509, in dispatch
    response = self.handle_exception(exc)
  File "D:\anaconda3\envs\Django\lib\site-packages\rest_framework\views.py", line 469, in handle_exception
    self.raise_uncaught_exception(exc)
  File "D:\anaconda3\envs\Django\lib\site-packages\rest_framework\views.py", line 480, in raise_uncaught_exception
    raise exc
  File "D:\anaconda3\envs\Django\lib\site-packages\rest_framework\views.py", line 497, in dispatch
    self.initial(request, *args, **kwargs)
  File "D:\anaconda3\envs\Django\lib\site-packages\rest_framework\views.py", line 415, in initial
    self.check_permissions(request)
  File "D:\anaconda3\envs\Django\lib\site-packages\rest_framework\views.py", line 332, in check_permissions
    if not permission.has_permission(request, self):
  File "E:\Work File\Background\BackEndServer\apps\system\permission.py", line 36, in has_permission
    perms = cache.get(request.user.username + '__perms')
  File "D:\anaconda3\envs\Django\lib\site-packages\django_redis\cache.py", line 92, in get
    value = self._get(key, default, version, client)
  File "D:\anaconda3\envs\Django\lib\site-packages\django_redis\cache.py", line 36, in _decorator
    raise e.__cause__
  File "D:\anaconda3\envs\Django\lib\site-packages\django_redis\client\default.py", line 258, in get
    value = client.get(key)
  File "D:\anaconda3\envs\Django\lib\site-packages\redis\commands\core.py", line 1829, in get
    return self.execute_command("GET", name)
  File "D:\anaconda3\envs\Django\lib\site-packages\redis\client.py", line 505, in execute_command
    conn = self.connection or pool.get_connection(command_name, **options)
  File "D:\anaconda3\envs\Django\lib\site-packages\redis\connection.py", line 1073, in get_connection
    connection.connect()
  File "D:\anaconda3\envs\Django\lib\site-packages\redis\connection.py", line 265, in connect
    raise ConnectionError(self._error_message(e))
redis.exceptions.ConnectionError: Error 11001 connecting to redis:6379. getaddrinfo failed.
[2023-08-23 09:51:43,891] [basehttp.py:161] [basehttp:log_message] [ERROR]- "GET /api/system/permissions/ HTTP/1.1" 500 154611
[2023-08-23 09:55:13,786] [autoreload.py:251] [autoreload:trigger_reload] [INFO]- E:\Work File\Background\BackEndServer\BackEndServer\settings.py changed, reloading.
[2023-08-23 09:55:16,188] [autoreload.py:637] [autoreload:run_with_reloader] [INFO]- Watching for file changes with StatReloader
[2023-08-23 09:55:21,951] [basehttp.py:161] [basehttp:log_message] [INFO]- "GET /api/docs/ HTTP/1.1" 200 160128
[2023-08-23 09:55:22,148] [basehttp.py:161] [basehttp:log_message] [INFO]- "GET /api/docs/schema.js HTTP/1.1" 200 24396
[2023-08-23 09:55:30,157] [basehttp.py:161] [basehttp:log_message] [INFO]- "GET /api/system/permissions/ HTTP/1.1" 200 4171
[2023-08-23 09:55:48,965] [log.py:224] [log:log_response] [ERROR]- Internal Server Error: /api/system/user/
Traceback (most recent call last):
  File "D:\anaconda3\envs\Django\lib\site-packages\rest_framework\fields.py", line 446, in get_attribute
    return get_attribute(instance, self.source_attrs)
  File "D:\anaconda3\envs\Django\lib\site-packages\rest_framework\fields.py", line 96, in get_attribute
    instance = getattr(instance, attr)
AttributeError: 'Permission' object has no attribute 'password'

During handling of the above exception, another exception occurred:

Traceback (most recent call last):
  File "D:\anaconda3\envs\Django\lib\site-packages\django\core\handlers\exception.py", line 47, in inner
    response = get_response(request)
  File "D:\anaconda3\envs\Django\lib\site-packages\django\core\handlers\base.py", line 181, in _get_response
    response = wrapped_callback(request, *callback_args, **callback_kwargs)
  File "D:\anaconda3\envs\Django\lib\site-packages\django\views\decorators\csrf.py", line 54, in wrapped_view
    return view_func(*args, **kwargs)
  File "D:\anaconda3\envs\Django\lib\site-packages\rest_framework\viewsets.py", line 125, in view
    return self.dispatch(request, *args, **kwargs)
  File "D:\anaconda3\envs\Django\lib\site-packages\rest_framework\views.py", line 509, in dispatch
    response = self.handle_exception(exc)
  File "D:\anaconda3\envs\Django\lib\site-packages\rest_framework\views.py", line 469, in handle_exception
    self.raise_uncaught_exception(exc)
  File "D:\anaconda3\envs\Django\lib\site-packages\rest_framework\views.py", line 480, in raise_uncaught_exception
    raise exc
  File "D:\anaconda3\envs\Django\lib\site-packages\rest_framework\views.py", line 506, in dispatch
    response = handler(request, *args, **kwargs)
  File "D:\anaconda3\envs\Django\lib\site-packages\rest_framework\mixins.py", line 46, in list
    return Response(serializer.data)
  File "D:\anaconda3\envs\Django\lib\site-packages\rest_framework\serializers.py", line 768, in data
    ret = super().data
  File "D:\anaconda3\envs\Django\lib\site-packages\rest_framework\serializers.py", line 253, in data
    self._data = self.to_representation(self.instance)
  File "D:\anaconda3\envs\Django\lib\site-packages\rest_framework\serializers.py", line 686, in to_representation
    return [
  File "D:\anaconda3\envs\Django\lib\site-packages\rest_framework\serializers.py", line 687, in <listcomp>
    self.child.to_representation(item) for item in iterable
  File "D:\anaconda3\envs\Django\lib\site-packages\rest_framework\serializers.py", line 509, in to_representation
    attribute = field.get_attribute(instance)
  File "D:\anaconda3\envs\Django\lib\site-packages\rest_framework\fields.py", line 479, in get_attribute
    raise type(exc)(msg)
AttributeError: Got AttributeError when attempting to get a value for field `password` on serializer `UserSerializer`.
The serializer field might be named incorrectly and not match any attribute or key on the `Permission` instance.
Original exception text was: 'Permission' object has no attribute 'password'.
[2023-08-23 09:55:48,976] [basehttp.py:161] [basehttp:log_message] [ERROR]- "GET /api/system/user/ HTTP/1.1" 500 166465
[2023-08-23 09:57:39,563] [autoreload.py:251] [autoreload:trigger_reload] [INFO]- E:\Work File\Background\BackEndServer\apps\system\views\users.py changed, reloading.
[2023-08-23 09:57:41,921] [autoreload.py:637] [autoreload:run_with_reloader] [INFO]- Watching for file changes with StatReloader
[2023-08-23 09:59:36,021] [autoreload.py:637] [autoreload:run_with_reloader] [INFO]- Watching for file changes with StatReloader
[2023-08-23 10:00:51,724] [basehttp.py:161] [basehttp:log_message] [INFO]- "GET /api/system/user/ HTTP/1.1" 200 523
[2023-08-23 10:01:08,616] [basehttp.py:161] [basehttp:log_message] [INFO]- "GET /api/system/user/1/ HTTP/1.1" 200 73
[2023-08-23 10:04:39,822] [basehttp.py:161] [basehttp:log_message] [INFO]- "GET /api/system/user/ HTTP/1.1" 200 523
[2023-08-23 10:05:33,783] [basehttp.py:161] [basehttp:log_message] [INFO]- "POST /api/token/ HTTP/1.1" 200 576
[2023-08-23 10:12:28,951] [autoreload.py:251] [autoreload:trigger_reload] [INFO]- E:\Work File\Background\BackEndServer\apps\system\serializers.py changed, reloading.
[2023-08-23 10:12:31,371] [autoreload.py:637] [autoreload:run_with_reloader] [INFO]- Watching for file changes with StatReloader
[2023-08-23 10:12:58,414] [autoreload.py:251] [autoreload:trigger_reload] [INFO]- E:\Work File\Background\BackEndServer\apps\system\models.py changed, reloading.
[2023-08-23 10:13:00,806] [autoreload.py:637] [autoreload:run_with_reloader] [INFO]- Watching for file changes with StatReloader
[2023-08-23 10:17:56,482] [autoreload.py:637] [autoreload:run_with_reloader] [INFO]- Watching for file changes with StatReloader
[2023-08-23 10:18:06,944] [basehttp.py:161] [basehttp:log_message] [INFO]- "GET /api/docs/ HTTP/1.1" 200 199850
[2023-08-23 10:18:07,077] [basehttp.py:161] [basehttp:log_message] [INFO]- "GET /api/docs/schema.js HTTP/1.1" 200 30332
[2023-08-23 10:19:13,978] [basehttp.py:161] [basehttp:log_message] [INFO]- "POST /api/system/register/ HTTP/1.1" 200 109
[2023-08-23 10:20:04,434] [basehttp.py:161] [basehttp:log_message] [INFO]- "GET /api/system/register/ HTTP/1.1" 200 228
[2023-08-23 10:20:43,447] [autoreload.py:251] [autoreload:trigger_reload] [INFO]- E:\Work File\Background\BackEndServer\apps\system\views\users.py changed, reloading.
[2023-08-23 10:20:45,827] [autoreload.py:637] [autoreload:run_with_reloader] [INFO]- Watching for file changes with StatReloader
[2023-08-23 10:22:09,727] [basehttp.py:161] [basehttp:log_message] [INFO]- "GET /api/docs/ HTTP/1.1" 200 199850
[2023-08-23 10:22:09,848] [basehttp.py:161] [basehttp:log_message] [INFO]- "GET /api/docs/schema.js HTTP/1.1" 200 30332
[2023-08-23 10:22:41,703] [basehttp.py:161] [basehttp:log_message] [INFO]- "POST /api/system/register/ HTTP/1.1" 200 238
[2023-08-23 10:23:07,119] [basehttp.py:161] [basehttp:log_message] [INFO]- "GET /api/system/register/ HTTP/1.1" 200 109
[2023-08-23 10:24:10,598] [autoreload.py:251] [autoreload:trigger_reload] [INFO]- E:\Work File\Background\BackEndServer\apps\system\views\users.py changed, reloading.
[2023-08-23 10:24:13,013] [autoreload.py:637] [autoreload:run_with_reloader] [INFO]- Watching for file changes with StatReloader
[2023-08-23 10:28:39,873] [autoreload.py:251] [autoreload:trigger_reload] [INFO]- E:\Work File\Background\BackEndServer\apps\system\models.py changed, reloading.
[2023-08-23 10:28:42,203] [autoreload.py:637] [autoreload:run_with_reloader] [INFO]- Watching for file changes with StatReloader
[2023-08-23 10:34:12,991] [autoreload.py:251] [autoreload:trigger_reload] [INFO]- E:\Work File\Background\BackEndServer\apps\system\admin.py changed, reloading.
[2023-08-23 10:34:15,421] [autoreload.py:637] [autoreload:run_with_reloader] [INFO]- Watching for file changes with StatReloader
[2023-08-23 10:38:18,391] [autoreload.py:251] [autoreload:trigger_reload] [INFO]- E:\Work File\Background\BackEndServer\apps\Account\models.py changed, reloading.
[2023-08-23 10:38:20,824] [autoreload.py:637] [autoreload:run_with_reloader] [INFO]- Watching for file changes with StatReloader
[2023-08-23 10:38:26,189] [autoreload.py:251] [autoreload:trigger_reload] [INFO]- E:\Work File\Background\BackEndServer\apps\Account\models.py changed, reloading.
[2023-08-23 10:38:28,434] [autoreload.py:637] [autoreload:run_with_reloader] [INFO]- Watching for file changes with StatReloader
[2023-08-23 10:38:37,383] [autoreload.py:251] [autoreload:trigger_reload] [INFO]- E:\Work File\Background\BackEndServer\apps\Account\models.py changed, reloading.
[2023-08-23 10:38:39,842] [autoreload.py:637] [autoreload:run_with_reloader] [INFO]- Watching for file changes with StatReloader
[2023-08-23 10:38:53,425] [autoreload.py:251] [autoreload:trigger_reload] [INFO]- E:\Work File\Background\BackEndServer\apps\Account\models.py changed, reloading.
[2023-08-23 10:38:55,734] [autoreload.py:637] [autoreload:run_with_reloader] [INFO]- Watching for file changes with StatReloader
[2023-08-23 10:39:35,725] [autoreload.py:251] [autoreload:trigger_reload] [INFO]- E:\Work File\Background\BackEndServer\apps\Account\models.py changed, reloading.
[2023-08-23 10:39:38,195] [autoreload.py:637] [autoreload:run_with_reloader] [INFO]- Watching for file changes with StatReloader
[2023-08-23 10:41:38,823] [autoreload.py:251] [autoreload:trigger_reload] [INFO]- E:\Work File\Background\BackEndServer\apps\Account\models.py changed, reloading.
[2023-08-23 10:41:41,193] [autoreload.py:637] [autoreload:run_with_reloader] [INFO]- Watching for file changes with StatReloader
[2023-08-23 10:42:36,541] [autoreload.py:251] [autoreload:trigger_reload] [INFO]- E:\Work File\Background\BackEndServer\apps\Account\models.py changed, reloading.
[2023-08-23 10:42:38,910] [autoreload.py:637] [autoreload:run_with_reloader] [INFO]- Watching for file changes with StatReloader
[2023-08-23 11:22:45,336] [autoreload.py:637] [autoreload:run_with_reloader] [INFO]- Watching for file changes with StatReloader
[2023-08-23 11:22:49,224] [basehttp.py:161] [basehttp:log_message] [INFO]- "GET / HTTP/1.1" 302 0
[2023-08-23 11:22:49,472] [basehttp.py:161] [basehttp:log_message] [INFO]- "GET /api/docs/ HTTP/1.1" 200 203477
[2023-08-23 11:22:49,555] [basehttp.py:161] [basehttp:log_message] [INFO]- "GET /api/docs/schema.js HTTP/1.1" 200 30444
[2023-08-23 11:22:59,001] [basehttp.py:161] [basehttp:log_message] [INFO]- "GET /api/system/user_info HTTP/1.1" 200 109
[2023-08-23 11:23:06,728] [basehttp.py:161] [basehttp:log_message] [INFO]- "GET /api/system/user_info HTTP/1.1" 200 109
[2023-08-23 11:23:20,338] [basehttp.py:161] [basehttp:log_message] [INFO]- "GET /api/docs/ HTTP/1.1" 200 203477
[2023-08-23 11:23:20,458] [basehttp.py:161] [basehttp:log_message] [INFO]- "GET /api/docs/schema.js HTTP/1.1" 200 30444
[2023-08-23 11:23:27,002] [basehttp.py:161] [basehttp:log_message] [INFO]- "GET /api/system/user_info HTTP/1.1" 200 109
[2023-08-23 11:26:50,794] [autoreload.py:251] [autoreload:trigger_reload] [INFO]- E:\Work File\Background\BackEndServer\apps\system\views\users.py changed, reloading.
[2023-08-23 11:26:53,287] [autoreload.py:637] [autoreload:run_with_reloader] [INFO]- Watching for file changes with StatReloader
[2023-08-23 11:28:16,510] [autoreload.py:251] [autoreload:trigger_reload] [INFO]- E:\Work File\Background\BackEndServer\apps\system\views\users.py changed, reloading.
[2023-08-23 11:28:18,937] [autoreload.py:637] [autoreload:run_with_reloader] [INFO]- Watching for file changes with StatReloader
[2023-08-23 11:33:31,582] [autoreload.py:251] [autoreload:trigger_reload] [INFO]- E:\Work File\Background\BackEndServer\apps\system\views\users.py changed, reloading.
[2023-08-23 11:33:33,975] [autoreload.py:637] [autoreload:run_with_reloader] [INFO]- Watching for file changes with StatReloader
[2023-08-23 11:33:35,940] [autoreload.py:251] [autoreload:trigger_reload] [INFO]- E:\Work File\Background\BackEndServer\apps\system\views\users.py changed, reloading.
[2023-08-23 11:33:38,265] [autoreload.py:637] [autoreload:run_with_reloader] [INFO]- Watching for file changes with StatReloader
[2023-08-23 11:34:22,959] [autoreload.py:251] [autoreload:trigger_reload] [INFO]- E:\Work File\Background\BackEndServer\apps\system\views\users.py changed, reloading.
[2023-08-23 11:34:25,312] [autoreload.py:637] [autoreload:run_with_reloader] [INFO]- Watching for file changes with StatReloader
[2023-08-23 11:34:28,980] [basehttp.py:161] [basehttp:log_message] [INFO]- "GET / HTTP/1.1" 302 0
[2023-08-23 11:34:29,214] [basehttp.py:161] [basehttp:log_message] [INFO]- "GET /api/docs/ HTTP/1.1" 200 171268
[2023-08-23 11:34:29,294] [basehttp.py:161] [basehttp:log_message] [INFO]- "GET /api/docs/schema.js HTTP/1.1" 200 25788
[2023-08-23 11:36:51,418] [autoreload.py:251] [autoreload:trigger_reload] [INFO]- E:\Work File\Background\BackEndServer\apps\system\views\users.py changed, reloading.
[2023-08-23 11:36:53,835] [autoreload.py:637] [autoreload:run_with_reloader] [INFO]- Watching for file changes with StatReloader
[2023-08-23 11:37:14,537] [autoreload.py:251] [autoreload:trigger_reload] [INFO]- E:\Work File\Background\BackEndServer\apps\system\views\users.py changed, reloading.
[2023-08-23 11:37:16,956] [autoreload.py:637] [autoreload:run_with_reloader] [INFO]- Watching for file changes with StatReloader
[2023-08-23 11:37:41,581] [autoreload.py:251] [autoreload:trigger_reload] [INFO]- E:\Work File\Background\BackEndServer\apps\system\views\users.py changed, reloading.
[2023-08-23 11:37:44,063] [autoreload.py:637] [autoreload:run_with_reloader] [INFO]- Watching for file changes with StatReloader
[2023-08-23 11:37:50,944] [autoreload.py:251] [autoreload:trigger_reload] [INFO]- E:\Work File\Background\BackEndServer\apps\system\views\users.py changed, reloading.
[2023-08-23 11:37:53,394] [autoreload.py:637] [autoreload:run_with_reloader] [INFO]- Watching for file changes with StatReloader
[2023-08-23 11:37:57,428] [autoreload.py:251] [autoreload:trigger_reload] [INFO]- E:\Work File\Background\BackEndServer\apps\system\views\users.py changed, reloading.
[2023-08-23 11:37:59,882] [autoreload.py:637] [autoreload:run_with_reloader] [INFO]- Watching for file changes with StatReloader
[2023-08-23 11:38:15,459] [autoreload.py:251] [autoreload:trigger_reload] [INFO]- E:\Work File\Background\BackEndServer\apps\system\views\users.py changed, reloading.
[2023-08-23 11:38:17,892] [autoreload.py:637] [autoreload:run_with_reloader] [INFO]- Watching for file changes with StatReloader
[2023-08-23 11:40:15,586] [autoreload.py:251] [autoreload:trigger_reload] [INFO]- E:\Work File\Background\BackEndServer\apps\system\views\users.py changed, reloading.
[2023-08-23 11:40:17,794] [autoreload.py:637] [autoreload:run_with_reloader] [INFO]- Watching for file changes with StatReloader
[2023-08-23 11:40:24,460] [autoreload.py:251] [autoreload:trigger_reload] [INFO]- E:\Work File\Background\BackEndServer\apps\system\views\users.py changed, reloading.
[2023-08-23 11:40:26,883] [autoreload.py:637] [autoreload:run_with_reloader] [INFO]- Watching for file changes with StatReloader
[2023-08-23 11:40:32,706] [basehttp.py:161] [basehttp:log_message] [INFO]- "GET / HTTP/1.1" 302 0
[2023-08-23 11:40:32,939] [basehttp.py:161] [basehttp:log_message] [INFO]- "GET /api/docs/ HTTP/1.1" 200 174901
[2023-08-23 11:40:33,019] [basehttp.py:161] [basehttp:log_message] [INFO]- "GET /api/docs/schema.js HTTP/1.1" 200 25948
[2023-08-23 11:40:41,345] [log.py:224] [log:log_response] [ERROR]- Internal Server Error: /api/system/Info/get_UserInfo/
Traceback (most recent call last):
  File "D:\anaconda3\envs\Django\lib\site-packages\django\core\handlers\exception.py", line 47, in inner
    response = get_response(request)
  File "D:\anaconda3\envs\Django\lib\site-packages\django\core\handlers\base.py", line 181, in _get_response
    response = wrapped_callback(request, *callback_args, **callback_kwargs)
  File "D:\anaconda3\envs\Django\lib\site-packages\django\views\decorators\csrf.py", line 54, in wrapped_view
    return view_func(*args, **kwargs)
  File "D:\anaconda3\envs\Django\lib\site-packages\rest_framework\viewsets.py", line 125, in view
    return self.dispatch(request, *args, **kwargs)
  File "D:\anaconda3\envs\Django\lib\site-packages\rest_framework\views.py", line 509, in dispatch
    response = self.handle_exception(exc)
  File "D:\anaconda3\envs\Django\lib\site-packages\rest_framework\views.py", line 469, in handle_exception
    self.raise_uncaught_exception(exc)
  File "D:\anaconda3\envs\Django\lib\site-packages\rest_framework\views.py", line 480, in raise_uncaught_exception
    raise exc
  File "D:\anaconda3\envs\Django\lib\site-packages\rest_framework\views.py", line 506, in dispatch
    response = handler(request, *args, **kwargs)
  File "E:\Work File\Background\BackEndServer\apps\system\views\users.py", line 56, in GetInfo
    return Response(serializer.data)
  File "D:\anaconda3\envs\Django\lib\site-packages\rest_framework\serializers.py", line 555, in data
    ret = super().data
  File "D:\anaconda3\envs\Django\lib\site-packages\rest_framework\serializers.py", line 257, in data
    self._data = self.get_initial()
  File "D:\anaconda3\envs\Django\lib\site-packages\rest_framework\serializers.py", line 405, in get_initial
    for field in self.fields.values()
  File "D:\anaconda3\envs\Django\lib\site-packages\django\utils\functional.py", line 48, in __get__
    res = instance.__dict__[self.name] = self.func(instance)
  File "D:\anaconda3\envs\Django\lib\site-packages\rest_framework\serializers.py", line 356, in fields
    for key, value in self.get_fields().items():
  File "D:\anaconda3\envs\Django\lib\site-packages\rest_framework\serializers.py", line 1076, in get_fields
    field_class, field_kwargs = self.build_field(
  File "D:\anaconda3\envs\Django\lib\site-packages\rest_framework\serializers.py", line 1222, in build_field
    return self.build_unknown_field(field_name, model_class)
  File "D:\anaconda3\envs\Django\lib\site-packages\rest_framework\serializers.py", line 1340, in build_unknown_field
    raise ImproperlyConfigured(
django.core.exceptions.ImproperlyConfigured: Field name `name` is not valid for model `User`.
[2023-08-23 11:40:41,357] [basehttp.py:161] [basehttp:log_message] [ERROR]- "GET /api/system/Info/get_UserInfo/ HTTP/1.1" 500 146370
[2023-08-23 11:41:41,054] [autoreload.py:251] [autoreload:trigger_reload] [INFO]- E:\Work File\Background\BackEndServer\apps\system\serializers.py changed, reloading.
[2023-08-23 11:41:43,442] [autoreload.py:637] [autoreload:run_with_reloader] [INFO]- Watching for file changes with StatReloader
[2023-08-23 11:41:51,255] [basehttp.py:161] [basehttp:log_message] [INFO]- "GET /api/system/Info/get_UserInfo/ HTTP/1.1" 200 118
[2023-08-23 11:45:55,374] [basehttp.py:161] [basehttp:log_message] [INFO]- "GET /api/system/Info/get_UserInfo/ HTTP/1.1" 200 118
[2023-08-23 11:57:01,868] [basehttp.py:161] [basehttp:log_message] [INFO]- "GET /api/system/Info/get_UserInfo/ HTTP/1.1" 200 118
[2023-08-23 11:57:54,901] [basehttp.py:161] [basehttp:log_message] [INFO]- "GET /api/system/Info/get_UserInfo/ HTTP/1.1" 200 118
[2023-08-23 14:10:42,408] [basehttp.py:161] [basehttp:log_message] [INFO]- "GET /api/system/Info/get_UserInfo/ HTTP/1.1" 200 60
[2023-08-23 14:12:13,190] [basehttp.py:161] [basehttp:log_message] [INFO]- "GET /api/system/Info/get_UserInfo/ HTTP/1.1" 200 60
[2023-08-23 14:18:18,817] [basehttp.py:161] [basehttp:log_message] [INFO]- "GET /api/system/Info/get_UserInfo/ HTTP/1.1" 200 60
[2023-08-23 14:22:33,190] [basehttp.py:161] [basehttp:log_message] [INFO]- "GET /api/system/groups/ HTTP/1.1" 200 259
[2023-08-23 14:23:23,297] [basehttp.py:161] [basehttp:log_message] [INFO]- "GET /api/system/groups/ HTTP/1.1" 200 184
[2023-08-23 14:24:07,596] [basehttp.py:161] [basehttp:log_message] [INFO]- "GET /api/system/Info/get_UserInfo/ HTTP/1.1" 200 118
[2023-08-23 14:31:23,690] [autoreload.py:251] [autoreload:trigger_reload] [INFO]- E:\Work File\Background\BackEndServer\apps\system\serializers.py changed, reloading.
[2023-08-23 14:31:26,327] [autoreload.py:637] [autoreload:run_with_reloader] [INFO]- Watching for file changes with StatReloader
[2023-08-23 14:31:51,534] [basehttp.py:161] [basehttp:log_message] [INFO]- "POST /api/token/ HTTP/1.1" 200 576
[2023-08-23 14:31:52,425] [basehttp.py:161] [basehttp:log_message] [INFO]- "GET /api/system/Info/get_UserInfo/ HTTP/1.1" 200 118
[2023-08-23 14:33:54,141] [basehttp.py:161] [basehttp:log_message] [INFO]- "POST /api/token/ HTTP/1.1" 200 576
[2023-08-23 14:33:55,002] [basehttp.py:161] [basehttp:log_message] [INFO]- "GET /api/system/Info/get_UserInfo/ HTTP/1.1" 200 118
[2023-08-24 09:55:23,247] [basehttp.py:161] [basehttp:log_message] [INFO]- "POST /api/token/ HTTP/1.1" 200 576
[2023-08-24 09:55:24,106] [basehttp.py:161] [basehttp:log_message] [INFO]- "GET /api/system/Info/get_UserInfo/ HTTP/1.1" 200 118
